program test.exceptions

IOError = object( "IOError" )

IOError->throw

e = IOError->caught()
display e

end
